Workbook
Name beed: Version!$B$247
Name board_transmu: #REF!
Name bsba: Version!$B$260:$B$261
Name bsed: Version!$B$236:$B$240
Name bsit: Version!$B$249:$B$257
Name btle: Version!$B$245
Name btvte: Version!$B$242:$B$243
Name cas: Version!$B$182:$B$186
Name cbs: Version!$B$189:$B$196
Name ccs: Version!$B$199:$B$202
Name cea: Version!$B$205:$B$211
Name chtm: Version!$B$214:$B$215
Name cit: Version!$B$218
Name coe: Version!$B$221:$B$227
Name colleges: Version!$B$171:$B$178
Name course_type: Version!$B$39:$B$46
Name cssp: Version!$B$230:$B$233
Name demo_percent: Version!$A$128:$B$131
Name Equivalent: 'New Grade Equivalent'!$A$2:$C$47
Name FINAL_GRADE_TRANSMUTATION: 'New Grade Equivalent'!$A$1:$C$46
Name fs_percent: Version!$A$121:$B$124
Name lab_percent: Version!$A$93:$B$97
Name lec_percent: Version!$A$86:$B$90
Name new_transmute: 'New Transmutation'!$A$3:$D$1048576
Name nonboard_transmu: #REF!
Name ojt_percent: Version!$A$114:$B$115
Name Old_Equivalent: 'Old Grade Equivalent'!$A$5:$C$49
Name old_transmute: 'Old Transmutation'!$A$2:$D$103
Name pe_percent: Version!$A$135:$B$139
Name raw_score_transmu: 'Transmutation 2'!$A$2:$C$103
Name raw_score_transmu: 'Transmutation 3'!$A$2:$C$103
Name res_percent: Version!$A$107:$B$109
Name shop_percent: Version!$A$100:$B$104
Name Strict_Transmu: 'Transmutation 2'!$A$3:$B$103
Name Strict_Transmu: 'Transmutation 3'!$A$3:$B$103
Name transmute: 'Old Transmutation'!$A$3:$D$1048576

Sheet Info
A1: DHVSU OFFICIAL CLASS RECORD v.1.5 (FOR FIRST AND SECOND YEAR ONLY)
A2: Course Information
A3: Class
A4: Program Type | B4: Non-board program
A5: Year Level | B5: Second Year
A6: Course Code
A7: Total Units | B7: 3/1
A8: Course Type | B8: Lecture
A9: Course Title | B9: Modeling and Simulation
A10: Course Description
A11: Acad. Year | B11: 2024-2025
A12: Term | B12: First Semester
A13: Session | B13: Tuesday 3:30 - 5:00 pm, Friday 2:00 - 3:30 pm
A15: Campus
A16: Campus | B16: DHVSU Bacolor
A17: College | B17: College of Education
A18: Department
A19: Program | B19: Bachelor of Secondary Education
A20: Major/ Specialization
A22: Faculty and Immediate Superior
A23: Faculty
A24: Faculty Rank | B24: Instructor I
A25: Program Coordinator
A26: Coordinator Position
A27: Chairperson
A28: Chairperson Position | B28: Area Chairperson
A29: Director/ Dean
A30: Director/ Dean Position | B30: Campus Director
A32: NEW Grading System
A34: Midterm | B34: =IF(AND(ISNUMBER(MATCH($B$5, {"Second Year","Third Year","Fourth Year","Fifth Year"}, 0)), $B$17="College of Engineering and Architecture"), 40%, 50%) -> 0.5
A35: Finals | B35: =IF(AND(ISNUMBER(MATCH($B$5, {"Second Year","Third Year","Fourth Year","Fifth Year"}, 0)), $B$17="College of Engineering and Architecture"), 60%, 50%) -> 0.5
A37: Criteria | B37: Percentage
A38: Attendance | B38: 0.1
A39: Major Exam | B39: 0.3
A40: Class Standing | B40: =SUM(B41:B45) -> 0.6
A41: Quizzes | B41: 0.3
A42: Recitation | B42: 0.1
A43: Other | B43: 0.1
A44: Activities | B44: 0.1
B45: 0
...

Sheet Student List
B2: CAMPUS | C2: =Info!B16 -> DHVSU Bacolor
B3: COURSE | C3: =Info!B6 -> 0
B4: TYPE | C4: =Info!B8 -> Lecture
B5: CLASS | C5: =Info!B3 -> 0
B6: SCHEDULE | C6: =Info!B13 -> Tuesday 3:30 - 5:00 pm, Friday 2:00 - 3:30 pm
A8: STUDENT MASTER LIST
A9: No. | B9: Student Number | C9: Student Full Name (Portal List) | D9: Sex | E9: Type 1 | F9: Type 2 | G9: Type 3 | H9: Type 4 | I9: Type 5 | J9: Type 6
A10: 1 | B10: 2010 | C10: xx,xx
A11: 2
A12: 3
A13: 4
A14: 5
A15: 6
A16: 7
A17: 8
A18: 9
A19: 10
A20: 11
A21: 12
A22: 13
... A94: 85

Sheet Midterm
A1: =MidCom!A1 -> DHVSU Bacolor Campus Modeling and Simulation Tuesday 3:30 - 5:00 pm, Friday 2:00 - 3:30 pm First Semester, A.Y. 2024-2025 LECTURE COURSE NON-BOARD PROGRAM MIDTERM | E1: No. | G1: =UPPER(Info!A38) -> ATTENDANCE | H1: =UPPER(Info!A40) -> CLASS STANDING | AL1: =UPPER(Info!A40) -> CLASS STANDING | AM1: MAJOR EXAM | AQ1: =UPPER(Info!A39) -> MAJOR EXAM | AR1: Adjustments | AS1: MIDTERM GRADE | AT1: EQUIVALENT | AU1: DESCRIPTIVE
E2: Date | M2: =UPPER(Info!A41) -> QUIZZES | S2: =UPPER(Info!A42) -> RECITATION | Y2: =UPPER(Info!A43) -> OTHER | AE2: =UPPER(Info!A44) -> ACTIVITIES | AK2: =UPPER(Info!A45)
E3: Details | F3: Attendance
A4: STUDENT MASTER LIST | D4: OFFICIALLY DROPPED? | E4: Weight | F4: 1 | G4: =MidCom!G4 -> 0.1 | H4: 1 | I4: 2 | J4: 3 | K4: 4 | L4: 5 | M4: =MidCom!M4 -> 0.3 | N4: 1 | O4: 2 | P4: 3 | Q4: 4 | R4: 5 | S4: =MidCom!S4 -> 0.1 | T4: 1 | U4: 2 | V4: 3 | W4: 4 | X4: 5 | Y4: =MidCom!Y4 -> 0.1 | Z4: 1 | AA4: 2 | AB4: 3 | AC4: 4 | AD4: 5 | AE4: =MidCom!AE4 -> 0.1 | AF4: 1 | AG4: 2 | AH4: 3 | AI4: 4 | AJ4: 5 | AK4: =MidCom!AK4 -> 0 | AL4: =MidCom!AL4 -> 0.6 | AM4: 1 | AN4: 2 | AO4: 3 | AP4: 4 | AQ4: =MidCom!AQ4 -> 0.3 | AR4: +
A5: No. | B5: Last Name | C5: First Name | E5: Items | F5: =MidCom!F5 -> 5 | H5: 30 | O5: 10 | T5: 10 | Z5: 10 | AP5: 100
A6: 1 | B6: =IF('Student List'!C10="","",UPPER(LEFT('Student List'!C10,FIND(",",'Student List'!C10)-1))) -> XX | C6: =IF('Student List'!C10="","",PROPER(MID('Student List'!C10, FIND(",", 'Student List'!C10) + 2, LEN('Student List'!C10) - FIND(",", 'Student List'!C10) - 1))) -> X | E6: =IF(MidCom!E6="","",MidCom!E6) -> FALSE | F6: =IF(B6="","",SUM(('MT Attendance'!AV4*5),('MT Attendance'!AW4*3),('MT Attendance'!AX4*2))) -> 0 | G6: =MidCom!G6 -> 60 | H6: 30 | M6: =MidCom!M6 -> 100 | O6: 10 | S6: =MidCom!S6 -> 100 | T6: 10 | Y6: =MidCom!Y6 -> 100 | Z6: 9 | AE6: =MidCom!AE6 -> 90 | AK6: =MidCom!AK6 -> 0 | AL6: =MidCom!AL6 -> 96.9 | AP6: 50 | AQ6: =MidCom!AQ6 -> 75 | AR6: 2 | AS6: =MidCom!AS6 -> 89.5 | AT6: =MidCom!AT6 -> 2 | AU6: =MidCom!AU6 -> Pass
A7: 2 | B7: =IF('Student List'!C11="","",UPPER(LEFT('Student List'!C11,FIND(",",'Student List'!C11)-1))) | C7: =IF('Student List'!C11="","",PROPER(MID('Student List'!C11, FIND(",", 'Student List'!C11) + 2, LEN('Student List'!C11) - FIND(",", 'Student List'!C11) - 1))) | E7: =IF(MidCom!E7="","",MidCom!E7) | F7: =IF(B7="","",SUM(('MT Attendance'!AV5*5),('MT Attendance'!AW5*3),('MT Attendance'!AX5*2))) | G7: =MidCom!G7 | M7: =MidCom!M7 | S7: =MidCom!S7 | Y7: =MidCom!Y7 | AE7: =MidCom!AE7 | AK7: =MidCom!AK7 | AL7: =MidCom!AL7 | AQ7: =MidCom!AQ7 | AS7: =MidCom!AS7 | AT7: =MidCom!AT7 | AU7: =MidCom!AU7
A8: 3 | B8: =IF('Student List'!C12="","",UPPER(LEFT('Student List'!C12,FIND(",",'Student List'!C12)-1))) | C8: =IF('Student List'!C12="","",PROPER(MID('Student List'!C12, FIND(",", 'Student List'!C12) + 2, LEN('Student List'!C12) - FIND(",", 'Student List'!C12) - 1))) | E8: =IF(MidCom!E8="","",MidCom!E8) | F8: =IF(B8="","",SUM(('MT Attendance'!AV6*5),('MT Attendance'!AW6*3),('MT Attendance'!AX6*2))) | G8: =MidCom!G8 | M8: =MidCom!M8 | S8: =MidCom!S8 | Y8: =MidCom!Y8 | AE8: =MidCom!AE8 | AK8: =MidCom!AK8 | AL8: =MidCom!AL8 | AQ8: =MidCom!AQ8 | AS8: =MidCom!AS8 | AT8: =MidCom!AT8 | AU8: =MidCom!AU8
A9: 4 | B9: =IF('Student List'!C13="","",UPPER(LEFT('Student List'!C13,FIND(",",'Student List'!C13)-1))) | C9: =IF('Student List'!C13="","",PROPER(MID('Student List'!C13, FIND(",", 'Student List'!C13) + 2, LEN('Student List'!C13) - FIND(",", 'Student List'!C13) - 1))) | E9: =IF(MidCom!E9="","",MidCom!E9) | F9: =IF(B9="","",SUM(('MT Attendance'!AV7*5),('MT Attendance'!AW7*3),('MT Attendance'!AX7*2))) | G9: =MidCom!G9 | M9: =MidCom!M9 | S9: =MidCom!S9 | Y9: =MidCom!Y9 | AE9: =MidCom!AE9 | AK9: =MidCom!AK9 | AL9: =MidCom!AL9 | AQ9: =MidCom!AQ9 | AS9: =MidCom!AS9 | AT9: =MidCom!AT9 | AU9: =MidCom!AU9
A10: 5 | B10: =IF('Student List'!C14="","",UPPER(LEFT('Student List'!C14,FIND(",",'Student List'!C14)-1))) | C10: =IF('Student List'!C14="","",PROPER(MID('Student List'!C14, FIND(",", 'Student List'!C14) + 2, LEN('Student List'!C14) - FIND(",", 'Student List'!C14) - 1))) | E10: =IF(MidCom!E10="","",MidCom!E10) | F10: =IF(B10="","",SUM(('MT Attendance'!AV8*5),('MT Attendance'!AW8*3),('MT Attendance'!AX8*2))) | G10: =MidCom!G10 | M10: =MidCom!M10 | S10: =MidCom!S10 | Y10: =MidCom!Y10 | AE10: =MidCom!AE10 | AK10: =MidCom!AK10 | AL10: =MidCom!AL10 | AQ10: =MidCom!AQ10 | AS10: =MidCom!AS10 | AT10: =MidCom!AT10 | AU10: =MidCom!AU10
A11: 6 | B11: =IF('Student List'!C15="","",UPPER(LEFT('Student List'!C15,FIND(",",'Student List'!C15)-1))) | C11: =IF('Student List'!C15="","",PROPER(MID('Student List'!C15, FIND(",", 'Student List'!C15) + 2, LEN('Student List'!C15) - FIND(",", 'Student List'!C15) - 1))) | E11: =IF(MidCom!E11="","",MidCom!E11) | F11: =IF(B11="","",SUM(('MT Attendance'!AV9*5),('MT Attendance'!AW9*3),('MT Attendance'!AX9*2))) | G11: =MidCom!G11 | M11: =MidCom!M11 | S11: =MidCom!S11 | Y11: =MidCom!Y11 | AE11: =MidCom!AE11 | AK11: =MidCom!AK11 | AL11: =MidCom!AL11 | AQ11: =MidCom!AQ11 | AS11: =MidCom!AS11 | AT11: =MidCom!AT11 | AU11: =MidCom!AU11
A12: 7 | B12: =IF('Student List'!C16="","",UPPER(LEFT('Student List'!C16,FIND(",",'Student List'!C16)-1))) | C12: =IF('Student List'!C16="","",PROPER(MID('Student List'!C16, FIND(",", 'Student List'!C16) + 2, LEN('Student List'!C16) - FIND(",", 'Student List'!C16) - 1))) | E12: =IF(MidCom!E12="","",MidCom!E12) | F12: =IF(B12="","",SUM(('MT Attendance'!AV10*5),('MT Attendance'!AW10*3),('MT Attendance'!AX10*2))) | G12: =MidCom!G12 | M12: =MidCom!M12 | S12: =MidCom!S12 | Y12: =MidCom!Y12 | AE12: =MidCom!AE12 | AK12: =MidCom!AK12 | AL12: =MidCom!AL12 | AQ12: =MidCom!AQ12 | AS12: =MidCom!AS12 | AT12: =MidCom!AT12 | AU12: =MidCom!AU12
A13: 8 | B13: =IF('Student List'!C17="","",UPPER(LEFT('Student List'!C17,FIND(",",'Student List'!C17)-1))) | C13: =IF('Student List'!C17="","",PROPER(MID('Student List'!C17, FIND(",", 'Student List'!C17) + 2, LEN('Student List'!C17) - FIND(",", 'Student List'!C17) - 1))) | E13: =IF(MidCom!E13="","",MidCom!E13) | F13: =IF(B13="","",SUM(('MT Attendance'!AV11*5),('MT Attendance'!AW11*3),('MT Attendance'!AX11*2))) | G13: =MidCom!G13 | M13: =MidCom!M13 | S13: =MidCom!S13 | Y13: =MidCom!Y13 | AE13: =MidCom!AE13 | AK13: =MidCom!AK13 | AL13: =MidCom!AL13 | AQ13: =MidCom!AQ13 | AS13: =MidCom!AS13 | AT13: =MidCom!AT13 | AU13: =MidCom!AU13
A14: 9 | B14: =IF('Student List'!C18="","",UPPER(LEFT('Student List'!C18,FIND(",",'Student List'!C18)-1))) | C14: =IF('Student List'!C18="","",PROPER(MID('Student List'!C18, FIND(",", 'Student List'!C18) + 2, LEN('Student List'!C18) - FIND(",", 'Student List'!C18) - 1))) | E14: =IF(MidCom!E14="","",MidCom!E14) | F14: =IF(B14="","",SUM(('MT Attendance'!AV12*5),('MT Attendance'!AW12*3),('MT Attendance'!AX12*2))) | G14: =MidCom!G14 | M14: =MidCom!M14 | S14: =MidCom!S14 | Y14: =MidCom!Y14 | AE14: =MidCom!AE14 | AK14: =MidCom!AK14 | AL14: =MidCom!AL14 | AQ14: =MidCom!AQ14 | AS14: =MidCom!AS14 | AT14: =MidCom!AT14 | AU14: =MidCom!AU14
A15: 10 | B15: =IF('Student List'!C19="","",UPPER(LEFT('Student List'!C19,FIND(",",'Student List'!C19)-1))) | C15: =IF('Student List'!C19="","",PROPER(MID('Student List'!C19, FIND(",", 'Student List'!C19) + 2, LEN('Student List'!C19) - FIND(",", 'Student List'!C19) - 1))) | E15: =IF(MidCom!E15="","",MidCom!E15) | F15: =IF(B15="","",SUM(('MT Attendance'!AV13*5),('MT Attendance'!AW13*3),('MT Attendance'!AX13*2))) | G15: =MidCom!G15 | M15: =MidCom!M15 | S15: =MidCom!S15 | Y15: =MidCom!Y15 | AE15: =MidCom!AE15 | AK15: =MidCom!AK15 | AL15: =MidCom!AL15 | AQ15: =MidCom!AQ15 | AS15: =MidCom!AS15 | AT15: =MidCom!AT15 | AU15: =MidCom!AU15
A16: 11 | B16: =IF('Student List'!C20="","",UPPER(LEFT('Student List'!C20,FIND(",",'Student List'!C20)-1))) | C16: =IF('Student List'!C20="","",PROPER(MID('Student List'!C20, FIND(",", 'Student List'!C20) + 2, LEN('Student List'!C20) - FIND(",", 'Student List'!C20) - 1))) | E16: =IF(MidCom!E16="","",MidCom!E16) | F16: =IF(B16="","",SUM(('MT Attendance'!AV14*5),('MT Attendance'!AW14*3),('MT Attendance'!AX14*2))) | G16: =MidCom!G16 | M16: =MidCom!M16 | S16: =MidCom!S16 | Y16: =MidCom!Y16 | AE16: =MidCom!AE16 | AK16: =MidCom!AK16 | AL16: =MidCom!AL16 | AQ16: =MidCom!AQ16 | AS16: =MidCom!AS16 | AT16: =MidCom!AT16 | AU16: =MidCom!AU16
A17: 12 | B17: =IF('Student List'!C21="","",UPPER(LEFT('Student List'!C21,FIND(",",'Student List'!C21)-1))) | C17: =IF('Student List'!C21="","",PROPER(MID('Student List'!C21, FIND(",", 'Student List'!C21) + 2, LEN('Student List'!C21) - FIND(",", 'Student List'!C21) - 1))) | E17: =IF(MidCom!E17="","",MidCom!E17) | F17: =IF(B17="","",SUM(('MT Attendance'!AV15*5),('MT Attendance'!AW15*3),('MT Attendance'!AX15*2))) | G17: =MidCom!G17 | M17: =MidCom!M17 | S17: =MidCom!S17 | Y17: =MidCom!Y17 | AE17: =MidCom!AE17 | AK17: =MidCom!AK17 | AL17: =MidCom!AL17 | AQ17: =MidCom!AQ17 | AS17: =MidCom!AS17 | AT17: =MidCom!AT17 | AU17: =MidCom!AU17
A18: 13 | B18: =IF('Student List'!C22="","",UPPER(LEFT('Student List'!C22,FIND(",",'Student List'!C22)-1))) | C18: =IF('Student List'!C22="","",PROPER(MID('Student List'!C22, FIND(",", 'Student List'!C22) + 2, LEN('Student List'!C22) - FIND(",", 'Student List'!C22) - 1))) | E18: =IF(MidCom!E18="","",MidCom!E18) | F18: =IF(B18="","",SUM(('MT Attendance'!AV16*5),('MT Attendance'!AW16*3),('MT Attendance'!AX16*2))) | G18: =MidCom!G18 | M18: =MidCom!M18 | S18: =MidCom!S18 | Y18: =MidCom!Y18 | AE18: =MidCom!AE18 | AK18: =MidCom!AK18 | AL18: =MidCom!AL18 | AQ18: =MidCom!AQ18 | AS18: =MidCom!AS18 | AT18: =MidCom!AT18 | AU18: =MidCom!AU18
... A39: 34 | B39: =IF('Student List'!C43="","",UPPER(LEFT('Student List'!C43,FIND(",",'Student List'!C43)-1))) | C39: =IF('Student List'!C43="","",PROPER(MID('Student List'!C43, FIND(",", 'Student List'!C43) + 2, LEN('Student List'!C43) - FIND(",", 'Student List'!C43) - 1))) | E39: =IF(MidCom!E39="","",MidCom!E39) | F39: =IF(B39="","",SUM(('MT Attendance'!AV37*5),('MT Attendance'!AW37*3),('MT Attendance'!AX37*2))) | G39: =MidCom!G39 | M39: =MidCom!M39 | S39: =MidCom!S39 | Y39: =MidCom!Y39 | AE39: =MidCom!AE39 | AK39: =MidCom!AK39 | AL39: =MidCom!AL39 | AQ39: =MidCom!AQ39 | AS39: =MidCom!AS39 | AT39: =MidCom!AT39 | AU39: =MidCom!AU39
A40: 35 | B40: =IF('Student List'!C44="","",UPPER(LEFT('Student List'!C44,FIND(",",'Student List'!C44)-1))) | C40: =IF('Student List'!C44="","",PROPER(MID('Student List'!C44, FIND(",", 'Student List'!C44) + 2, LEN('Student List'!C44) - FIND(",", 'Student List'!C44) - 1))) | E40: =IF(MidCom!E40="","",MidCom!E40) | F40: =IF(B40="","",SUM(('MT Attendance'!AV38*5),('MT Attendance'!AW38*3),('MT Attendance'!AX38*2))) | G40: =MidCom!G40 | M40: =MidCom!M40 | S40: =MidCom!S40 | Y40: =MidCom!Y40 | AE40: =MidCom!AE40 | AK40: =MidCom!AK40 | AL40: =MidCom!AL40 | AQ40: =MidCom!AQ40 | AR40: 1 | AS40: =MidCom!AS40 | AT40: =MidCom!AT40 | AU40: =MidCom!AU40
A41: 36 | B41: =IF('Student List'!C45="","",UPPER(LEFT('Student List'!C45,FIND(",",'Student List'!C45)-1))) | C41: =IF('Student List'!C45="","",PROPER(MID('Student List'!C45, FIND(",", 'Student List'!C45) + 2, LEN('Student List'!C45) - FIND(",", 'Student List'!C45) - 1))) | E41: =IF(MidCom!E41="","",MidCom!E41) | F41: =IF(B41="","",SUM(('MT Attendance'!AV39*5),('MT Attendance'!AW39*3),('MT Attendance'!AX39*2))) | G41: =MidCom!G41 | M41: =MidCom!M41 | S41: =MidCom!S41 | Y41: =MidCom!Y41 | AE41: =MidCom!AE41 | AK41: =MidCom!AK41 | AL41: =MidCom!AL41 | AQ41: =MidCom!AQ41 | AS41: =MidCom!AS41 | AT41: =MidCom!AT41 | AU41: =MidCom!AU41
A42: 37 | B42: =IF('Student List'!C46="","",UPPER(LEFT('Student List'!C46,FIND(",",'Student List'!C46)-1))) | C42: =IF('Student List'!C46="","",PROPER(MID('Student List'!C46, FIND(",", 'Student List'!C46) + 2, LEN('Student List'!C46) - FIND(",", 'Student List'!C46) - 1))) | E42: =IF(MidCom!E42="","",MidCom!E42) | F42: =IF(B42="","",SUM(('MT Attendance'!AV40*5),('MT Attendance'!AW40*3),('MT Attendance'!AX40*2))) | G42: =MidCom!G42 | M42: =MidCom!M42 | S42: =MidCom!S42 | Y42: =MidCom!Y42 | AE42: =MidCom!AE42 | AK42: =MidCom!AK42 | AL42: =MidCom!AL42 | AQ42: =MidCom!AQ42 | AS42: =MidCom!AS42 | AT42: =MidCom!AT42 | AU42: =MidCom!AU42
A43: 38 | B43: =IF('Student List'!C47="","",UPPER(LEFT('Student List'!C47,FIND(",",'Student List'!C47)-1))) | C43: =IF('Student List'!C47="","",PROPER(MID('Student List'!C47, FIND(",", 'Student List'!C47) + 2, LEN('Student List'!C47) - FIND(",", 'Student List'!C47) - 1))) | E43: =IF(MidCom!E43="","",MidCom!E43) | F43: =IF(B43="","",SUM(('MT Attendance'!AV41*5),('MT Attendance'!AW41*3),('MT Attendance'!AX41*2))) | G43: =MidCom!G43 | M43: =MidCom!M43 | S43: =MidCom!S43 | Y43: =MidCom!Y43 | AE43: =MidCom!AE43 | AK43: =MidCom!AK43 | AL43: =MidCom!AL43 | AQ43: =MidCom!AQ43 | AS43: =MidCom!AS43 | AT43: =MidCom!AT43 | AU43: =MidCom!AU43
A44: 39 | B44: =IF('Student List'!C48="","",UPPER(LEFT('Student List'!C48,FIND(",",'Student List'!C48)-1))) | C44: =IF('Student List'!C48="","",PROPER(MID('Student List'!C48, FIND(",", 'Student List'!C48) + 2, LEN('Student List'!C48) - FIND(",", 'Student List'!C48) - 1))) | E44: =IF(MidCom!E44="","",MidCom!E44) | F44: =IF(B44="","",SUM(('MT Attendance'!AV42*5),('MT Attendance'!AW42*3),('MT Attendance'!AX42*2))) | G44: =MidCom!G44 | M44: =MidCom!M44 | S44: =MidCom!S44 | Y44: =MidCom!Y44 | AE44: =MidCom!AE44 | AK44: =MidCom!AK44 | AL44: =MidCom!AL44 | AQ44: =MidCom!AQ44 | AS44: =MidCom!AS44 | AT44: =MidCom!AT44 | AU44: =MidCom!AU44
A45: 40 | B45: =IF('Student List'!C49="","",UPPER(LEFT('Student List'!C49,FIND(",",'Student List'!C49)-1))) | C45: =IF('Student List'!C49="","",PROPER(MID('Student List'!C49, FIND(",", 'Student List'!C49) + 2, LEN('Student List'!C49) - FIND(",", 'Student List'!C49) - 1))) | E45: =IF(MidCom!E45="","",MidCom!E45) | F45: =IF(B45="","",SUM(('MT Attendance'!AV43*5),('MT Attendance'!AW43*3),('MT Attendance'!AX43*2))) | G45: =MidCom!G45 | M45: =MidCom!M45 | S45: =MidCom!S45 | Y45: =MidCom!Y45 | AE45: =MidCom!AE45 | AK45: =MidCom!AK45 | AL45: =MidCom!AL45 | AQ45: =MidCom!AQ45 | AS45: =MidCom!AS45 | AT45: =MidCom!AT45 | AU45: =MidCom!AU45
A46: 41 | B46: =IF('Student List'!C50="","",UPPER(LEFT('Student List'!C50,FIND(",",'Student List'!C50)-1))) | C46: =IF('Student List'!C50="","",PROPER(MID('Student List'!C50, FIND(",", 'Student List'!C50) + 2, LEN('Student List'!C50) - FIND(",", 'Student List'!C50) - 1))) | E46: =IF(MidCom!E46="","",MidCom!E46) | F46: =IF(B46="","",SUM(('MT Attendance'!AV44*5),('MT Attendance'!AW44*3),('MT Attendance'!AX44*2))) | G46: =MidCom!G46 | M46: =MidCom!M46 | S46: =MidCom!S46 | Y46: =MidCom!Y46 | AE46: =MidCom!AE46 | AK46: =MidCom!AK46 | AL46: =MidCom!AL46 | AQ46: =MidCom!AQ46 | AS46: =MidCom!AS46 | AT46: =MidCom!AT46 | AU46: =MidCom!AU46
A47: 42 | B47: =IF('Student List'!C51="","",UPPER(LEFT('Student List'!C51,FIND(",",'Student List'!C51)-1))) | C47: =IF('Student List'!C51="","",PROPER(MID('Student List'!C51, FIND(",", 'Student List'!C51) + 2, LEN('Student List'!C51) - FIND(",", 'Student List'!C51) - 1))) | E47: =IF(MidCom!E47="","",MidCom!E47) | F47: =IF(B47="","",SUM(('MT Attendance'!AV45*5),('MT Attendance'!AW45*3),('MT Attendance'!AX45*2))) | G47: =MidCom!G47 | M47: =MidCom!M47 | S47: =MidCom!S47 | Y47: =MidCom!Y47 | AE47: =MidCom!AE47 | AK47: =MidCom!AK47 | AL47: =MidCom!AL47 | AQ47: =MidCom!AQ47 | AS47: =MidCom!AS47 | AT47: =MidCom!AT47 | AU47: =MidCom!AU47
A48: 43 | B48: =IF('Student List'!C52="","",UPPER(LEFT('Student List'!C52,FIND(",",'Student List'!C52)-1))) | C48: =IF('Student List'!C52="","",PROPER(MID('Student List'!C52, FIND(",", 'Student List'!C52) + 2, LEN('Student List'!C52) - FIND(",", 'Student List'!C52) - 1))) | E48: =IF(MidCom!E48="","",MidCom!E48) | F48: =IF(B48="","",SUM(('MT Attendance'!AV46*5),('MT Attendance'!AW46*3),('MT Attendance'!AX46*2))) | G48: =MidCom!G48 | M48: =MidCom!M48 | S48: =MidCom!S48 | Y48: =MidCom!Y48 | AE48: =MidCom!AE48 | AK48: =MidCom!AK48 | AL48: =MidCom!AL48 | AQ48: =MidCom!AQ48 | AS48: =MidCom!AS48 | AT48: =MidCom!AT48 | AU48: =MidCom!AU48
A49: 44 | B49: =IF('Student List'!C53="","",UPPER(LEFT('Student List'!C53,FIND(",",'Student List'!C53)-1))) | C49: =IF('Student List'!C53="","",PROPER(MID('Student List'!C53, FIND(",", 'Student List'!C53) + 2, LEN('Student List'!C53) - FIND(",", 'Student List'!C53) - 1))) | E49: =IF(MidCom!E49="","",MidCom!E49) | F49: =IF(B49="","",SUM(('MT Attendance'!AV47*5),('MT Attendance'!AW47*3),('MT Attendance'!AX47*2))) | G49: =MidCom!G49 | M49: =MidCom!M49 | S49: =MidCom!S49 | Y49: =MidCom!Y49 | AE49: =MidCom!AE49 | AK49: =MidCom!AK49 | AL49: =MidCom!AL49 | AQ49: =MidCom!AQ49 | AS49: =MidCom!AS49 | AT49: =MidCom!AT49 | AU49: =MidCom!AU49
A50: 45 | B50: =IF('Student List'!C54="","",UPPER(LEFT('Student List'!C54,FIND(",",'Student List'!C54)-1))) | C50: =IF('Student List'!C54="","",PROPER(MID('Student List'!C54, FIND(",", 'Student List'!C54) + 2, LEN('Student List'!C54) - FIND(",", 'Student List'!C54) - 1))) | E50: =IF(MidCom!E50="","",MidCom!E50) | F50: =IF(B50="","",SUM(('MT Attendance'!AV48*5),('MT Attendance'!AW48*3),('MT Attendance'!AX48*2))) | G50: =MidCom!G50 | M50: =MidCom!M50 | S50: =MidCom!S50 | Y50: =MidCom!Y50 | AE50: =MidCom!AE50 | AK50: =MidCom!AK50 | AL50: =MidCom!AL50 | AQ50: =MidCom!AQ50 | AS50: =MidCom!AS50 | AT50: =MidCom!AT50 | AU50: =MidCom!AU50
A51: 46 | B51: =IF('Student List'!C55="","",UPPER(LEFT('Student List'!C55,FIND(",",'Student List'!C55)-1))) | C51: =IF('Student List'!C55="","",PROPER(MID('Student List'!C55, FIND(",", 'Student List'!C55) + 2, LEN('Student List'!C55) - FIND(",", 'Student List'!C55) - 1))) | E51: =IF(MidCom!E51="","",MidCom!E51) | F51: =IF(B51="","",SUM(('MT Attendance'!AV49*5),('MT Attendance'!AW49*3),('MT Attendance'!AX49*2))) | G51: =MidCom!G51 | M51: =MidCom!M51 | S51: =MidCom!S51 | Y51: =MidCom!Y51 | AE51: =MidCom!AE51 | AK51: =MidCom!AK51 | AL51: =MidCom!AL51 | AQ51: =MidCom!AQ51 | AS51: =MidCom!AS51 | AT51: =MidCom!AT51 | AU51: =MidCom!AU51
A52: 47 | B52: =IF('Student List'!C56="","",UPPER(LEFT('Student List'!C56,FIND(",",'Student List'!C56)-1))) | C52: =IF('Student List'!C56="","",PROPER(MID('Student List'!C56, FIND(",", 'Student List'!C56) + 2, LEN('Student List'!C56) - FIND(",", 'Student List'!C56) - 1))) | E52: =IF(MidCom!E52="","",MidCom!E52) | F52: =IF(B52="","",SUM(('MT Attendance'!AV50*5),('MT Attendance'!AW50*3),('MT Attendance'!AX50*2))) | G52: =MidCom!G52 | M52: =MidCom!M52 | S52: =MidCom!S52 | Y52: =MidCom!Y52 | AE52: =MidCom!AE52 | AK52: =MidCom!AK52 | AL52: =MidCom!AL52 | AQ52: =MidCom!AQ52 | AS52: =MidCom!AS52 | AT52: =MidCom!AT52 | AU52: =MidCom!AU52
... A90: 85 | B90: =IF('Student List'!C94="","",UPPER(LEFT('Student List'!C94,FIND(",",'Student List'!C94)-1))) | C90: =IF('Student List'!C94="","",PROPER(MID('Student List'!C94, FIND(",", 'Student List'!C94) + 2, LEN('Student List'!C94) - FIND(",", 'Student List'!C94) - 1))) | E90: =IF(MidCom!E90="","",MidCom!E90) | F90: =IF(B90="","",SUM(('MT Attendance'!AV88*5),('MT Attendance'!AW88*3),('MT Attendance'!AX88*2))) | G90: =MidCom!G90 | M90: =MidCom!M90 | S90: =MidCom!S90 | Y90: =MidCom!Y90 | AE90: =MidCom!AE90 | AK90: =MidCom!AK90 | AL90: =MidCom!AL90 | AQ90: =MidCom!AQ90 | AS90: =MidCom!AS90 | AT90: =MidCom!AT90 | AU90: =MidCom!AU90

Sheet MidCom
A1: =Info!B16&" Campus"&CHAR(10) &CHAR(10)&Info!B6&CHAR(10)&Info!B9 &CHAR(10) &CHAR(10) &Info!B13 &CHAR(10) &CHAR(10) &Info!B12&", A.Y. "&Info!B11 &CHAR(10) &CHAR(10) &UPPER(Info!B8) &" COURSE" &CHAR(10) &CHAR(10) &UPPER(Info!B4) &CHAR(10) &CHAR(10) &"MIDTERM" -> DHVSU Bacolor Campus Modeling and Simulation Tuesday 3:30 - 5:00 pm, Friday 2:00 - 3:30 pm First Semester, A.Y. 2024-2025 LECTURE COURSE NON-BOARD PROGRAM MIDTERM | G1: =UPPER(Info!A38) -> ATTENDANCE | H1: =UPPER(Info!A40) -> CLASS STANDING | AL1: =UPPER(Info!A40) -> CLASS STANDING | AM1: =UPPER(Info!A40) -> CLASS STANDING | AQ1: =UPPER(Info!A39) -> MAJOR EXAM | AR1: Adjustments | AS1: MIDTERM GRADE | AT1: EQUIVALENT | AU1: DESCRIPTIVE
E2: Date | H2: =IF(Midterm!H2="","",Midterm!H2) | I2: =IF(Midterm!I2="","",Midterm!I2) | J2: =IF(Midterm!J2="","",Midterm!J2) | K2: =IF(Midterm!K2="","",Midterm!K2) | L2: =IF(Midterm!L2="","",Midterm!L2) | M2: =UPPER(Info!A41) -> QUIZZES | N2: =IF(Midterm!N2="","",Midterm!N2) | O2: =IF(Midterm!O2="","",Midterm!O2) | P2: =IF(Midterm!P2="","",Midterm!P2) | Q2: =IF(Midterm!Q2="","",Midterm!Q2) | R2: =IF(Midterm!R2="","",Midterm!R2) | S2: =UPPER(Info!A42) -> RECITATION | T2: =IF(Midterm!T2="","",Midterm!T2) | U2: =IF(Midterm!U2="","",Midterm!U2) | V2: =IF(Midterm!V2="","",Midterm!V2) | W2: =IF(Midterm!W2="","",Midterm!W2) | X2: =IF(Midterm!X2="","",Midterm!X2) | Y2: =UPPER(Info!A43) -> OTHER | Z2: =IF(Midterm!Z2="","",Midterm!Z2) | AA2: =IF(Midterm!AA2="","",Midterm!AA2) | AB2: =IF(Midterm!AB2="","",Midterm!AB2) | AC2: =IF(Midterm!AC2="","",Midterm!AC2) | AD2: =IF(Midterm!AD2="","",Midterm!AD2) | AE2: =UPPER(Info!A44) -> ACTIVITIES | AF2: =IF(Midterm!AF2="","",Midterm!AF2) | AG2: =IF(Midterm!AG2="","",Midterm!AG2) | AH2: =IF(Midterm!AH2="","",Midterm!AH2) | AI2: =IF(Midterm!AI2="","",Midterm!AI2) | AJ2: =IF(Midterm!AJ2="","",Midterm!AJ2) | AK2: =UPPER(Info!A45) | AM2: =IF(Midterm!AM2="","",Midterm!AM2) | AN2: =IF(Midterm!AN2="","",Midterm!AN2) | AO2: =IF(Midterm!AO2="","",Midterm!AO2) | AP2: =IF(Midterm!AP2="","",Midterm!AP2)
E3: Details | F3: Attendance | H3: =IF(Midterm!H3="","",Midterm!H3) | I3: =IF(Midterm!I3="","",Midterm!I3) | J3: =IF(Midterm!J3="","",Midterm!J3) | K3: =IF(Midterm!K3="","",Midterm!K3) | L3: =IF(Midterm!L3="","",Midterm!L3) | N3: =IF(Midterm!N3="","",Midterm!N3) | O3: =IF(Midterm!O3="","",Midterm!O3) | P3: =IF(Midterm!P3="","",Midterm!P3) | Q3: =IF(Midterm!Q3="","",Midterm!Q3) | R3: =IF(Midterm!R3="","",Midterm!R3) | T3: =IF(Midterm!T3="","",Midterm!T3) | U3: =IF(Midterm!U3="","",Midterm!U3) | V3: =IF(Midterm!V3="","",Midterm!V3) | W3: =IF(Midterm!W3="","",Midterm!W3) | X3: =IF(Midterm!X3="","",Midterm!X3) | Z3: =IF(Midterm!Z3="","",Midterm!Z3) | AA3: =IF(Midterm!AA3="","",Midterm!AA3) | AB3: =IF(Midterm!AB3="","",Midterm!AB3) | AC3: =IF(Midterm!AC3="","",Midterm!AC3) | AD3: =IF(Midterm!AD3="","",Midterm!AD3) | AF3: =IF(Midterm!AF3="","",Midterm!AF3) | AG3: =IF(Midterm!AG3="","",Midterm!AG3) | AH3: =IF(Midterm!AH3="","",Midterm!AH3) | AI3: =IF(Midterm!AI3="","",Midterm!AI3) | AJ3: =IF(Midterm!AJ3="","",Midterm!AJ3) | AM3: =IF(Midterm!AM3="","",Midterm!AM3) | AN3: =IF(Midterm!AN3="","",Midterm!AN3) | AO3: =IF(Midterm!AO3="","",Midterm!AO3) | AP3: =IF(Midterm!AP3="","",Midterm!AP3)
A4: STUDENT MASTER LIST | D4: OFFICIALLY DROPPED? | E4: No. | F4: 1 | G4: =Info!B38 -> 0.1 | H4: 1 | I4: 2 | J4: 3 | K4: 4 | L4: 5 | M4: =Info!B41 -> 0.3 | N4: 1 | O4: 2 | P4: 3 | Q4: 4 | R4: 5 | S4: =Info!B42 -> 0.1 | T4: 1 | U4: 2 | V4: 3 | W4: 4 | X4: 5 | Y4: =Info!B43 -> 0.1 | Z4: 1 | AA4: 2 | AB4: 3 | AC4: 4 | AD4: 5 | AE4: =Info!B44 -> 0.1 | AF4: 1 | AG4: 2 | AH4: 3 | AI4: 4 | AJ4: 5 | AK4: =Info!B45 -> 0 | AL4: =Info!B40 -> 0.6 | AM4: 1 | AN4: 2 | AO4: 3 | AP4: 4 | AQ4: =Info!B39 -> 0.3 | AR4: +
A5: No. | B5: Last Name | C5: First Name | E5: Items | F5: =COUNTA('MT Attendance'!C2:AU2)*5 -> 5 | H5: =IF(Midterm!H5="","",Midterm!H5) -> 30 | I5: =IF(Midterm!I5="","",Midterm!I5) | J5: =IF(Midterm!J5="","",Midterm!J5) | K5: =IF(Midterm!K5="","",Midterm!K5) | L5: =IF(Midterm!L5="","",Midterm!L5) | N5: =IF(Midterm!N5="","",Midterm!N5) | O5: =IF(Midterm!O5="","",Midterm!O5) -> 10 | P5: =IF(Midterm!P5="","",Midterm!P5) | Q5: =IF(Midterm!Q5="","",Midterm!Q5) | R5: =IF(Midterm!R5="","",Midterm!R5) | T5: =IF(Midterm!T5="","",Midterm!T5) -> 10 | U5: =IF(Midterm!U5="","",Midterm!U5) | V5: =IF(Midterm!V5="","",Midterm!V5) | W5: =IF(Midterm!W5="","",Midterm!W5) | X5: =IF(Midterm!X5="","",Midterm!X5) | Z5: =IF(Midterm!Z5="","",Midterm!Z5) -> 10 | AA5: =IF(Midterm!AA5="","",Midterm!AA5) | AB5: =IF(Midterm!AB5="","",Midterm!AB5) | AC5: =IF(Midterm!AC5="","",Midterm!AC5) | AD5: =IF(Midterm!AD5="","",Midterm!AD5) | AF5: =IF(Midterm!AF5="","",Midterm!AF5) | AG5: =IF(Midterm!AG5="","",Midterm!AG5) | AH5: =IF(Midterm!AH5="","",Midterm!AH5) | AI5: =IF(Midterm!AI5="","",Midterm!AI5) | AJ5: =IF(Midterm!AJ5="","",Midterm!AJ5) | AM5: =IF(Midterm!AM5="","",Midterm!AM5) | AN5: =IF(Midterm!AN5="","",Midterm!AN5) | AO5: =IF(Midterm!AO5="","",Midterm!AO5) | AP5: =IF(Midterm!AP5="","",Midterm!AP5) -> 100
A6: 1 | B6: =IF('Student List'!C10="","",UPPER(LEFT('Student List'!C10,FIND(",",'Student List'!C10)-1))) -> XX | C6: =IF('Student List'!C10="","",PROPER(MID('Student List'!C10, FIND(",", 'Student List'!C10) + 2, LEN('Student List'!C10) - FIND(",", 'Student List'!C10) - 1))) -> X | D6: =IF(B6="","",IF(Midterm!D6="", "NA", Midterm!D6)) -> NA | E6: =IF(B6="","", IF(Info!$B$5="First Year", IF(D6="Yes", "DRP", IF(D6="No", "WF", "") ) ) ) -> FALSE | F6: =IF($B6="","", IF(F$5="","", IF(Midterm!F6="",0, IF(NOT(ISNUMBER(Midterm!F6)),"NAN", IF(Midterm!F6<0,"NEG", IF(Midterm!F6>F$5,"OVER", IF(AND(F$5<=100,Midterm!F6>100),"ERR", IF(Info!$B$4="Non-board program", IF(OR(AND(F$5>0,F$5>100),AND(F$5>0,F$5<100)), VLOOKUP(FLOOR((Midterm!F6/F$5)*100,1),new_transmute,2,FALSE), VLOOKUP(Midterm!F6,new_transmute,2,FALSE) ), IF(Info!$B$4="Board program", IF(OR(AND(F$5>0,F$5>100),AND(F$5>0,F$5<100)), VLOOKUP(FLOOR((Midterm!F6/F$5)*100,1),new_transmute,3,FALSE), VLOOKUP(Midterm!F6,new_transmute,3,FALSE) ), IF(Info!$B$4="Board program (Medicine)", IF(OR(AND(F$5>0,F$5>100),AND(F$5>0,F$5<100)), VLOOKUP(FLOOR((Midterm!F6/F$5)*100,1),new_transmute,4,FALSE), VLOOKUP(Midterm!F6,new_transmute,4,FALSE) ), "" ) ) ) ) ) ) ) ) )) -> 60 | G6: =IF(B6="","",F6) -> 60 | H6: =IF($B6="","", IF(H$5="","", IF(Midterm!H6="",0, IF(NOT(ISNUMBER(Midterm!H6)),"NAN", IF(Midterm!H6<0,"NEG", IF(Midterm!H6>H$5,"OVER", IF(AND(H$5<=100,Midterm!H6>100),"ERR", IF(Info!$B$4="Non-board program", IF(OR(AND(H$5>0,H$5>100),AND(H$5>0,H$5<100)), VLOOKUP(FLOOR((Midterm!H6/H$5)*100,1),new_transmute,2,FALSE), VLOOKUP(Midterm!H6,new_transmute,2,FALSE) ), IF(Info!$B$4="Board program", IF(OR(AND(H$5>0,H$5>100),AND(H$5>0,H$5<100)), VLOOKUP(FLOOR((Midterm!H6/H$5)*100,1),new_transmute,3,FALSE), VLOOKUP(Midterm!H6,new_transmute,3,FALSE) ), IF(Info!$B$4="Board program (Medicine)", IF(OR(AND(H$5>0,H$5>100),AND(H$5>0,H$5<100)), VLOOKUP(FLOOR((Midterm!H6/H$5)*100,1),new_transmute,4,FALSE), VLOOKUP(Midterm!H6,new_transmute,4,FALSE) ), "" ) ) ) ) ) ) ) ) )) -> 100 | I6: =IF($B6="","", IF(I$5="","", IF(Midterm!I6="",0, IF(NOT(ISNUMBER(Midterm!I6)),"NAN", IF(Midterm!I6<0,"NEG", IF(Midterm!I6>I$5,"OVER", IF(AND(I$5<=100,Midterm!I6>100),"ERR", IF(Info!$B$4="Non-board program", IF(OR(AND(I$5>0,I$5>100),AND(I$5>0,I$5<100)), VLOOKUP(FLOOR((Midterm!I6/I$5)*100,1),new_transmute,2,FALSE), VLOOKUP(Midterm!I6,new_transmute,2,FALSE) ), IF(Info!$B$4="Board program", IF(OR(AND(I$5>0,I$5>100),AND(I$5>0,I$5<100)), VLOOKUP(FLOOR((Midterm!I6/I$5)*100,1),new_transmute,3,FALSE), VLOOKUP(Midterm!I6,new_transmute,3,FALSE) ), IF(Info!$B$4="Board program (Medicine)", IF(OR(AND(I$5>0,I$5>100),AND(I$5>0,I$5<100)), VLOOKUP(FLOOR((Midterm!I6/I$5)*100,1),new_transmute,4,FALSE), VLOOKUP(Midterm!I6,new_transmute,4,FALSE) ), "" ) ) ) ) ) ) ) ) )) | J6: =IF($B6="","", IF(J$5="","", IF(Midterm!J6="",0, IF(NOT(ISNUMBER(Midterm!J6)),"NAN", IF(Midterm!J6<0,"NEG", IF(Midterm!J6>J$5,"OVER", IF(AND(J$5<=100,Midterm!J6>100),"ERR", IF(Info!$B$4="Non-board program", IF(OR(AND(J$5>0,J$5>100),AND(J$5>0,J$5<100)), VLOOKUP(FLOOR((Midterm!J6/J$5)*100,1),new_transmute,2,FALSE), VLOOKUP(Midterm!J6,new_transmute,2,FALSE) ), IF(Info!$B$4="Board program", IF(OR(AND(J$5>0,J$5>100),AND(J$5>0,J$5<100)), VLOOKUP(FLOOR((Midterm!J6/J$5)*100,1),new_transmute,3,FALSE), VLOOKUP(Midterm!J6,new_transmute,3,FALSE) ), IF(Info!$B$4="Board program (Medicine)", IF(OR(AND(J$5>0,J$5>100),AND(J$5>0,J$5<100)), VLOOKUP(FLOOR((Midterm!J6/J$5)*100,1),new_transmute,4,FALSE), VLOOKUP(Midterm!J6,new_transmute,4,FALSE) ), "" ) ) ) ) ) ) ) ) )) | K6: =IF($B6="","", IF(K$5="","", IF(Midterm!K6="",0, IF(NOT(ISNUMBER(Midterm!K6)),"NAN", IF(Midterm!K6<0,"NEG", IF(Midterm!K6>K$5,"OVER", IF(AND(K$5<=100,Midterm!K6>100),"ERR", IF(Info!$B$4="Non-board program", IF(OR(AND(K$5>0,K$5>100),AND(K$5>0,K$5<100)), VLOOKUP(FLOOR((Midterm!K6/K$5)*100,1),new_transmute,2,FALSE), VLOOKUP(Midterm!K6,new_transmute,2,FALSE) ), IF(Info!$B$4="Board program", IF(OR(AND(K$5>0,K$5>100),AND(K$5>0,K$5<100)), VLOOKUP(FLOOR((Midterm!K6/K$5)*100,1),new_transmute,3,FALSE), VLOOKUP(Midterm!K6,new_transmute,3,FALSE) ), IF(Info!$B$4="Board program (Medicine)", IF(OR(AND(K$5>0,K$5>100),AND(K$5>0,K$5<100)), VLOOKUP(FLOOR((Midterm!K6/K$5)*100,1),new_transmute,4,FALSE), VLOOKUP(Midterm!K6,new_transmute,4,FALSE) ), "" ) ) ) ) ) ) ) ) )) | L6: =IF($B6="","", IF(L$5="","", IF(Midterm!L6="",0, IF(NOT(ISNUMBER(Midterm!L6)),"NAN", IF(Midterm!L6<0,"NEG", IF(Midterm!L6>L$5,"OVER", IF(AND(L$5<=100,Midterm!L6>100),"ERR", IF(Info!$B$4="Non-board program", IF(OR(AND(L$5>0,L$5>100),AND(L$5>0,L$5<100)), VLOOKUP(FLOOR((Midterm!L6/L$5)*100,1),new_transmute,2,FALSE), VLOOKUP(Midterm!L6,new_transmute,2,FALSE) ), IF(Info!$B$4="Board program", IF(OR(AND(L$5>0,L$5>100),AND(L$5>0,L$5<100)), VLOOKUP(FLOOR((Midterm!L6/L$5)*100,1),new_transmute,3,FALSE), VLOOKUP(Midterm!L6,new_transmute,3,FALSE) ), IF(Info!$B$4="Board program (Medicine)", IF(OR(AND(L$5>0,L$5>100),AND(L$5>0,L$5<100)), VLOOKUP(FLOOR((Midterm!L6/L$5)*100,1),new_transmute,4,FALSE), VLOOKUP(Midterm!L6,new_transmute,4,FALSE) ), "" ) ) ) ) ) ) ) ) )) | M6: =IF(B6="", "", IF(COUNTIF(H6:L6, "OVER") > 0, "OVER", IFERROR(AVERAGEIF(H6:L6, "<>OVER"), 0))) -> 100 | N6: =IF($B6="","", IF(N$5="","", IF(Midterm!N6="",0, IF(NOT(ISNUMBER(Midterm!N6)),"NAN", IF(Midterm!N6<0,"NEG", IF(Midterm!N6>N$5,"OVER", IF(AND(N$5<=100,Midterm!N6>100),"ERR", IF(Info!$B$4="Non-board program", IF(OR(AND(N$5>0,N$5>100),AND(N$5>0,N$5<100)), VLOOKUP(FLOOR((Midterm!N6/N$5)*100,1),new_transmute,2,FALSE), VLOOKUP(Midterm!N6,new_transmute,2,FALSE) ), IF(Info!$B$4="Board program", IF(OR(AND(N$5>0,N$5>100),AND(N$5>0,N$5<100)), VLOOKUP(FLOOR((Midterm!N6/N$5)*100,1),new_transmute,3,FALSE), VLOOKUP(Midterm!N6,new_transmute,3,FALSE) ), IF(Info!$B$4="Board program (Medicine)", IF(OR(AND(N$5>0,N$5>100),AND(N$5>0,N$5<100)), VLOOKUP(FLOOR((Midterm!N6/N$5)*100,1),new_transmute,4,FALSE), VLOOKUP(Midterm!N6,new_transmute,4,FALSE) ), "" ) ) ) ) ) ) ) ) )) | O6: =IF($B6="","", IF(O$5="","", IF(Midterm!O6="",0, IF(NOT(ISNUMBER(Midterm!O6)),"NAN", IF(Midterm!O6<0,"NEG", IF(Midterm!O6>O$5,"OVER", IF(AND(O$5<=100,Midterm!O6>100),"ERR", IF(Info!$B$4="Non-board program", IF(OR(AND(O$5>0,O$5>100),AND(O$5>0,O$5<100)), VLOOKUP(FLOOR((Midterm!O6/O$5)*100,1),new_transmute,2,FALSE), VLOOKUP(Midterm!O6,new_transmute,2,FALSE) ), IF(Info!$B$4="Board program", IF(OR(AND(O$5>0,O$5>100),AND(O$5>0,O$5<100)), VLOOKUP(FLOOR((Midterm!O6/O$5)*100,1),new_transmute,3,FALSE), VLOOKUP(Midterm!O6,new_transmute,3,FALSE) ), IF(Info!$B$4="Board program (Medicine)", IF(OR(AND(O$5>0,O$5>100),AND(O$5>0,O$5<100)), VLOOKUP(FLOOR((Midterm!O6/O$5)*100,1),new_transmute,4,FALSE), VLOOKUP(Midterm!O6,new_transmute,4,FALSE) ), "" ) ) ) ) ) ) ) ) )) -> 100 | P6: =IF($B6="","", IF(P$5="","", IF(Midterm!P6="",0, IF(NOT(ISNUMBER(Midterm!P6)),"NAN", IF(Midterm!P6<0,"NEG", IF(Midterm!P6>P$5,"OVER", IF(AND(P$5<=100,Midterm!P6>100),"ERR", IF(Info!$B$4="Non-board program", IF(OR(AND(P$5>0,P$5>100),AND(P$5>0,P$5<100)), VLOOKUP(FLOOR((Midterm!P6/P$5)*100,1),new_transmute,2,FALSE), VLOOKUP(Midterm!P6,new_transmute,2,FALSE) ), IF(Info!$B$4="Board program", IF(OR(AND(P$5>0,P$5>100),AND(P$5>0,P$5<100)), VLOOKUP(FLOOR((Midterm!P6/P$5)*100,1),new_transmute,3,FALSE), VLOOKUP(Midterm!P6,new_transmute,3,FALSE) ), IF(Info!$B$4="Board program (Medicine)", IF(OR(AND(P$5>0,P$5>100),AND(P$5>0,P$5<100)), VLOOKUP(FLOOR((Midterm!P6/P$5)*100,1),new_transmute,4,FALSE), VLOOKUP(Midterm!P6,new_transmute,4,FALSE) ), "" ) ) ) ) ) ) ) ) )) | Q6: =IF($B6="","", IF(Q$5="","", IF(Midterm!Q6="",0, IF(NOT(ISNUMBER(Midterm!Q6)),"NAN", IF(Midterm!Q6<0,"NEG", IF(Midterm!Q6>Q$5,"OVER", IF(AND(Q$5<=100,Midterm!Q6>100),"ERR", IF(Info!$B$4="Non-board program", IF(OR(AND(Q$5>0,Q$5>100),AND(Q$5>0,Q$5<100)), VLOOKUP(FLOOR((Midterm!Q6/Q$5)*100,1),new_transmute,2,FALSE), VLOOKUP(Midterm!Q6,new_transmute,2,FALSE) ), IF(Info!$B$4="Board program", IF(OR(AND(Q$5>0,Q$5>100),AND(Q$5>0,Q$5<100)), VLOOKUP(FLOOR((Midterm!Q6/Q$5)*100,1),new_transmute,3,FALSE), VLOOKUP(Midterm!Q6,new_transmute,3,FALSE) ), IF(Info!$B$4="Board program (Medicine)", IF(OR(AND(Q$5>0,Q$5>100),AND(Q$5>0,Q$5<100)), VLOOKUP(FLOOR((Midterm!Q6/Q$5)*100,1),new_transmute,4,FALSE), VLOOKUP(Midterm!Q6,new_transmute,4,FALSE) ), "" ) ) ) ) ) ) ) ) )) | R6: =IF($B6="","", IF(R$5="","", IF(Midterm!R6="",0, IF(NOT(ISNUMBER(Midterm!R6)),"NAN", IF(Midterm!R6<0,"NEG", IF(Midterm!R6>R$5,"OVER", IF(AND(R$5<=100,Midterm!R6>100),"ERR", IF(Info!$B$4="Non-board program", IF(OR(AND(R$5>0,R$5>100),AND(R$5>0,R$5<100)), VLOOKUP(FLOOR((Midterm!R6/R$5)*100,1),new_transmute,2,FALSE), VLOOKUP(Midterm!R6,new_transmute,2,FALSE) ), IF(Info!$B$4="Board program", IF(OR(AND(R$5>0,R$5>100),AND(R$5>0,R$5<100)), VLOOKUP(FLOOR((Midterm!R6/R$5)*100,1),new_transmute,3,FALSE), VLOOKUP(Midterm!R6,new_transmute,3,FALSE) ), IF(Info!$B$4="Board program (Medicine)", IF(OR(AND(R$5>0,R$5>100),AND(R$5>0,R$5<100)), VLOOKUP(FLOOR((Midterm!R6/R$5)*100,1),new_transmute,4,FALSE), VLOOKUP(Midterm!R6,new_transmute,4,FALSE) ), "" ) ) ) ) ) ) ) ) )) | S6: =IF(B6="", "", IF(COUNTIF(N6:R6, "OVER") > 0, "OVER", IFERROR(AVERAGEIF(N6:R6, "<>OVER"), 0))) -> 100 | T6: =IF($B6="","", IF(T$5="","", IF(Midterm!T6="",0, IF(NOT(ISNUMBER(Midterm!T6)),"NAN", IF(Midterm!T6<0,"NEG", IF(Midterm!T6>T$5,"OVER", IF(AND(T$5<=100,Midterm!T6>100),"ERR", IF(Info!$B$4="Non-board program", IF(OR(AND(T$5>0,T$5>100),AND(T$5>0,T$5<100)), VLOOKUP(FLOOR((Midterm!T6/T$5)*100,1),new_transmute,2,FALSE), VLOOKUP(Midterm!T6,new_transmute,2,FALSE) ), IF(Info!$B$4="Board program", IF(OR(AND(T$5>0,T$5>100),AND(T$5>0,T$5<100)), VLOOKUP(FLOOR((Midterm!T6/T$5)*100,1),new_transmute,3,FALSE), VLOOKUP(Midterm!T6,new_transmute,3,FALSE) ), IF(Info!$B$4="Board program (Medicine)", IF(OR(AND(T$5>0,T$5>100),AND(T$5>0,T$5<100)), VLOOKUP(FLOOR((Midterm!T6/T$5)*100,1),new_transmute,4,FALSE), VLOOKUP(Midterm!T6,new_transmute,4,FALSE) ), "" ) ) ) ) ) ) ) ) )) -> 100 | U6: =IF($B6="","", IF(U$5="","", IF(Midterm!U6="",0, IF(NOT(ISNUMBER(Midterm!U6)),"NAN", IF(Midterm!U6<0,"NEG", IF(Midterm!U6>U$5,"OVER", IF(AND(U$5<=100,Midterm!U6>100),"ERR", IF(Info!$B$4="Non-board program", IF(OR(AND(U$5>0,U$5>100),AND(U$5>0,U$5<100)), VLOOKUP(FLOOR((Midterm!U6/U$5)*100,1),new_transmute,2,FALSE), VLOOKUP(Midterm!U6,new_transmute,2,FALSE) ), IF(Info!$B$4="Board program", IF(OR(AND(U$5>0,U$5>100),AND(U$5>0,U$5<100)), VLOOKUP(FLOOR((Midterm!U6/U$5)*100,1),new_transmute,3,FALSE), VLOOKUP(Midterm!U6,new_transmute,3,FALSE) ), IF(Info!$B$4="Board program (Medicine)", IF(OR(AND(U$5>0,U$5>100),AND(U$5>0,U$5<100)), VLOOKUP(FLOOR((Midterm!U6/U$5)*100,1),new_transmute,4,FALSE), VLOOKUP(Midterm!U6,new_transmute,4,FALSE) ), "" ) ) ) ) ) ) ) ) )) | V6: =IF($B6="","", IF(V$5="","", IF(Midterm!V6="",0, IF(NOT(ISNUMBER(Midterm!V6)),"NAN", IF(Midterm!V6<0,"NEG", IF(Midterm!V6>V$5,"OVER", IF(AND(V$5<=100,Midterm!V6>100),"ERR", IF(Info!$B$4="Non-board program", IF(OR(AND(V$5>0,V$5>100),AND(V$5>0,V$5<100)), VLOOKUP(FLOOR((Midterm!V6/V$5)*100,1),new_transmute,2,FALSE), VLOOKUP(Midterm!V6,new_transmute,2,FALSE) ), IF(Info!$B$4="Board program", IF(OR(AND(V$5>0,V$5>100),AND(V$5>0,V$5<100)), VLOOKUP(FLOOR((Midterm!V6/V$5)*100,1),new_transmute,3,FALSE), VLOOKUP(Midterm!V6,new_transmute,3,FALSE) ), IF(Info!$B$4="Board program (Medicine)", IF(OR(AND(V$5>0,V$5>100),AND(V$5>0,V$5<100)), VLOOKUP(FLOOR((Midterm!V6/V$5)*100,1),new_transmute,4,FALSE), VLOOKUP(Midterm!V6,new_transmute,4,FALSE) ), "" ) ) ) ) ) ) ) ) )) | W6: =IF($B6="","", IF(W$5="","", IF(Midterm!W6="",0, IF(NOT(ISNUMBER(Midterm!W6)),"NAN", IF(Midterm!W6<0,"NEG", IF(Midterm!W6>W$5,"OVER", IF(AND(W$5<=100,Midterm!W6>100),"ERR", IF(Info!$B$4="Non-board program", IF(OR(AND(W$5>0,W$5>100),AND(W$5>0,W$5<100)), VLOOKUP(FLOOR((Midterm!W6/W$5)*100,1),new_transmute,2,FALSE), VLOOKUP(Midterm!W6,new_transmute,2,FALSE) ), IF(Info!$B$4="Board program", IF(OR(AND(W$5>0,W$5>100),AND(W$5>0,W$5<100)), VLOOKUP(FLOOR((Midterm!W6/W$5)*100,1),new_transmute,3,FALSE), VLOOKUP(Midterm!W6,new_transmute,3,FALSE) ), IF(Info!$B$4="Board program (Medicine)", IF(OR(AND(W$5>0,W$5>100),AND(W$5>0,W$5<100)), VLOOKUP(FLOOR((Midterm!W6/W$5)*100,1),new_transmute,4,FALSE), VLOOKUP(Midterm!W6,new_transmute,4,FALSE) ), "" ) ) ) ) ) ) ) ) )) | X6: =IF($B6="","", IF(X$5="","", IF(Midterm!X6="",0, IF(NOT(ISNUMBER(Midterm!X6)),"NAN", IF(Midterm!X6<0,"NEG", IF(Midterm!X6>X$5,"OVER", IF(AND(X$5<=100,Midterm!X6>100),"ERR", IF(Info!$B$4="Non-board program", IF(OR(AND(X$5>0,X$5>100),AND(X$5>0,X$5<100)), VLOOKUP(FLOOR((Midterm!X6/X$5)*100,1),new_transmute,2,FALSE), VLOOKUP(Midterm!X6,new_transmute,2,FALSE) ), IF(Info!$B$4="Board program", IF(OR(AND(X$5>0,X$5>100),AND(X$5>0,X$5<100)), VLOOKUP(FLOOR((Midterm!X6/X$5)*100,1),new_transmute,3,FALSE), VLOOKUP(Midterm!X6,new_transmute,3,FALSE) ), IF(Info!$B$4="Board program (Medicine)", IF(OR(AND(X$5>0,X$5>100),AND(X$5>0,X$5<100)), VLOOKUP(FLOOR((Midterm!X6/X$5)*100,1),new_transmute,4,FALSE), VLOOKUP(Midterm!X6,new_transmute,4,FALSE) ), "" ) ) ) ) ) ) ) ) )) | Y6: =IF(B6="", "", IF(COUNTIF(T6:X6, "OVER") > 0, "OVER", IFERROR(AVERAGEIF(T6:X6, "<>OVER"), 0))) -> 100 | Z6: =IF($B6="","", IF(Z$5="","", IF(Midterm!Z6="",0, IF(NOT(ISNUMBER(Midterm!Z6)),"NAN", IF(Midterm!Z6<0,"NEG", IF(Midterm!Z6>Z$5,"OVER", IF(AND(Z$5<=100,Midterm!Z6>100),"ERR", IF(Info!$B$4="Non-board program", IF(OR(AND(Z$5>0,Z$5>100),AND(Z$5>0,Z$5<100)), VLOOKUP(FLOOR((Midterm!Z6/Z$5)*100,1),new_transmute,2,FALSE), VLOOKUP(Midterm!Z6,new_transmute,2,FALSE) ), IF(Info!$B$4="Board program", IF(OR(AND(Z$5>0,Z$5>100),AND(Z$5>0,Z$5<100)), VLOOKUP(FLOOR((Midterm!Z6/Z$5)*100,1),new_transmute,3,FALSE), VLOOKUP(Midterm!Z6,new_transmute,3,FALSE) ), IF(Info!$B$4="Board program (Medicine)", IF(OR(AND(Z$5>0,Z$5>100),AND(Z$5>0,Z$5<100)), VLOOKUP(FLOOR((Midterm!Z6/Z$5)*100,1),new_transmute,4,FALSE), VLOOKUP(Midterm!Z6,new_transmute,4,FALSE) ), "" ) ) ) ) ) ) ) ) )) -> 90 | AA6: =IF($B6="","", IF(AA$5="","", IF(Midterm!AA6="",0, IF(NOT(ISNUMBER(Midterm!AA6)),"NAN", IF(Midterm!AA6<0,"NEG", IF(Midterm!AA6>AA$5,"OVER", IF(AND(AA$5<=100,Midterm!AA6>100),"ERR", IF(Info!$B$4="Non-board program", IF(OR(AND(AA$5>0,AA$5>100),AND(AA$5>0,AA$5<100)), VLOOKUP(FLOOR((Midterm!AA6/AA$5)*100,1),new_transmute,2,FALSE), VLOOKUP(Midterm!AA6,new_transmute,2,FALSE) ), IF(Info!$B$4="Board program", IF(OR(AND(AA$5>0,AA$5>100),AND(AA$5>0,AA$5<100)), VLOOKUP(FLOOR((Midterm!AA6/AA$5)*100,1),new_transmute,3,FALSE), VLOOKUP(Midterm!AA6,new_transmute,3,FALSE) ), IF(Info!$B$4="Board program (Medicine)", IF(OR(AND(AA$5>0,AA$5>100),AND(AA$5>0,AA$5<100)), VLOOKUP(FLOOR((Midterm!AA6/AA$5)*100,1),new_transmute,4,FALSE), VLOOKUP(Midterm!AA6,new_transmute,4,FALSE) ), "" ) ) ) ) ) ) ) ) )) | AB6: =IF($B6="","", IF(AB$5="","", IF(Midterm!AB6="",0, IF(NOT(ISNUMBER(Midterm!AB6)),"NAN", IF(Midterm!AB6<0,"NEG", IF(Midterm!AB6>AB$5,"OVER", IF(AND(AB$5<=100,Midterm!AB6>100),"ERR", IF(Info!$B$4="Non-board program", IF(OR(AND(AB$5>0,AB$5>100),AND(AB$5>0,AB$5<100)), VLOOKUP(FLOOR((Midterm!AB6/AB$5)*100,1),new_transmute,2,FALSE), VLOOKUP(Midterm!AB6,new_transmute,2,FALSE) ), IF(Info!$B$4="Board program", IF(OR(AND(AB$5>0,AB$5>100),AND(AB$5>0,AB$5<100)), VLOOKUP(FLOOR((Midterm!AB6/AB$5)*100,1),new_transmute,3,FALSE), VLOOKUP(Midterm!AB6,new_transmute,3,FALSE) ), IF(Info!$B$4="Board program (Medicine)", IF(OR(AND(AB$5>0,AB$5>100),AND(AB$5>0,AB$5<100)), VLOOKUP(FLOOR((Midterm!AB6/AB$5)*100,1),new_transmute,4,FALSE), VLOOKUP(Midterm!AB6,new_transmute,4,FALSE) ), "" ) ) ) ) ) ) ) ) )) | AC6: =IF($B6="","", IF(AC$5="","", IF(Midterm!AC6="",0, IF(NOT(ISNUMBER(Midterm!AC6)),"NAN", IF(Midterm!AC6<0,"NEG", IF(Midterm!AC6>AC$5,"OVER", IF(AND(AC$5<=100,Midterm!AC6>100),"ERR", IF(Info!$B$4="Non-board program", IF(OR(AND(AC$5>0,AC$5>100),AND(AC$5>0,AC$5<100)), VLOOKUP(FLOOR((Midterm!AC6/AC$5)*100,1),new_transmute,2,FALSE), VLOOKUP(Midterm!AC6,new_transmute,2,FALSE) ), IF(Info!$B$4="Board program", IF(OR(AND(AC$5>0,AC$5>100),AND(AC$5>0,AC$5<100)), VLOOKUP(FLOOR((Midterm!AC6/AC$5)*100,1),new_transmute,3,FALSE), VLOOKUP(Midterm!AC6,new_transmute,3,FALSE) ), IF(Info!$B$4="Board program (Medicine)", IF(OR(AND(AC$5>0,AC$5>100),AND(AC$5>0,AC$5<100)), VLOOKUP(FLOOR((Midterm!AC6/AC$5)*100,1),new_transmute,4,FALSE), VLOOKUP(Midterm!AC6,new_transmute,4,FALSE) ), "" ) ) ) ) ) ) ) ) )) | AD6: =IF($B6="","", IF(AD$5="","", IF(Midterm!AD6="",0, IF(NOT(ISNUMBER(Midterm!AD6)),"NAN", IF(Midterm!AD6<0,"NEG", IF(Midterm!AD6>AD$5,"OVER", IF(AND(AD$5<=100,Midterm!AD6>100),"ERR", IF(Info!$B$4="Non-board program", IF(OR(AND(AD$5>0,AD$5>100),AND(AD$5>0,AD$5<100)), VLOOKUP(FLOOR((Midterm!AD6/AD$5)*100,1),new_transmute,2,FALSE), VLOOKUP(Midterm!AD6,new_transmute,2,FALSE) ), IF(Info!$B$4="Board program", IF(OR(AND(AD$5>0,AD$5>100),AND(AD$5>0,AD$5<100)), VLOOKUP(FLOOR((Midterm!AD6/AD$5)*100,1),new_transmute,3,FALSE), VLOOKUP(Midterm!AD6,new_transmute,3,FALSE) ), IF(Info!$B$4="Board program (Medicine)", IF(OR(AND(AD$5>0,AD$5>100),AND(AD$5>0,AD$5<100)), VLOOKUP(FLOOR((Midterm!AD6/AD$5)*100,1),new_transmute,4,FALSE), VLOOKUP(Midterm!AD6,new_transmute,4,FALSE) ), "" ) ) ) ) ) ) ) ) )) | AE6: =IF(B6="", "", IF(COUNTIF(Z6:AD6, "OVER") > 0, "OVER", IFERROR(AVERAGEIF(Z6:AD6, "<>OVER"), 0))) -> 90 | AF6: =IF($B6="","", IF(AF$5="","", IF(Midterm!AF6="",0, IF(NOT(ISNUMBER(Midterm!AF6)),"NAN", IF(Midterm!AF6<0,"NEG", IF(Midterm!AF6>AF$5,"OVER", IF(AND(AF$5<=100,Midterm!AF6>100),"ERR", IF(Info!$B$4="Non-board program", IF(OR(AND(AF$5>0,AF$5>100),AND(AF$5>0,AF$5<100)), VLOOKUP(FLOOR((Midterm!AF6/AF$5)*100,1),new_transmute,2,FALSE), VLOOKUP(Midterm!AF6,new_transmute,2,FALSE) ), IF(Info!$B$4="Board program", IF(OR(AND(AF$5>0,AF$5>100),AND(AF$5>0,AF$5<100)), VLOOKUP(FLOOR((Midterm!AF6/AF$5)*100,1),new_transmute,3,FALSE), VLOOKUP(Midterm!AF6,new_transmute,3,FALSE) ), IF(Info!$B$4="Board program (Medicine)", IF(OR(AND(AF$5>0,AF$5>100),AND(AF$5>0,AF$5<100)), VLOOKUP(FLOOR((Midterm!AF6/AF$5)*100,1),new_transmute,4,FALSE), VLOOKUP(Midterm!AF6,new_transmute,4,FALSE) ), "" ) ) ) ) ) ) ) ) )) | AG6: =IF($B6="","", IF(AG$5="","", IF(Midterm!AG6="",0, IF(NOT(ISNUMBER(Midterm!AG6)),"NAN", IF(Midterm!AG6<0,"NEG", IF(Midterm!AG6>AG$5,"OVER", IF(AND(AG$5<=100,Midterm!AG6>100),"ERR", IF(Info!$B$4="Non-board program", IF(OR(AND(AG$5>0,AG$5>100),AND(AG$5>0,AG$5<100)), VLOOKUP(FLOOR((Midterm!AG6/AG$5)*100,1),new_transmute,2,FALSE), VLOOKUP(Midterm!AG6,new_transmute,2,FALSE) ), IF(Info!$B$4="Board program", IF(OR(AND(AG$5>0,AG$5>100),AND(AG$5>0,AG$5<100)), VLOOKUP(FLOOR((Midterm!AG6/AG$5)*100,1),new_transmute,3,FALSE), VLOOKUP(Midterm!AG6,new_transmute,3,FALSE) ), IF(Info!$B$4="Board program (Medicine)", IF(OR(AND(AG$5>0,AG$5>100),AND(AG$5>0,AG$5<100)), VLOOKUP(FLOOR((Midterm!AG6/AG$5)*100,1),new_transmute,4,FALSE), VLOOKUP(Midterm!AG6,new_transmute,4,FALSE) ), "" ) ) ) ) ) ) ) ) )) | AH6: =IF($B6="","", IF(AH$5="","", IF(Midterm!AH6="",0, IF(NOT(ISNUMBER(Midterm!AH6)),"NAN", IF(Midterm!AH6<0,"NEG", IF(Midterm!AH6>AH$5,"OVER", IF(AND(AH$5<=100,Midterm!AH6>100),"ERR", IF(Info!$B$4="Non-board program", IF(OR(AND(AH$5>0,AH$5>100),AND(AH$5>0,AH$5<100)), VLOOKUP(FLOOR((Midterm!AH6/AH$5)*100,1),new_transmute,2,FALSE), VLOOKUP(Midterm!AH6,new_transmute,2,FALSE) ), IF(Info!$B$4="Board program", IF(OR(AND(AH$5>0,AH$5>100),AND(AH$5>0,AH$5<100)), VLOOKUP(FLOOR((Midterm!AH6/AH$5)*100,1),new_transmute,3,FALSE), VLOOKUP(Midterm!AH6,new_transmute,3,FALSE) ), IF(Info!$B$4="Board program (Medicine)", IF(OR(AND(AH$5>0,AH$5>100),AND(AH$5>0,AH$5<100)), VLOOKUP(FLOOR((Midterm!AH6/AH$5)*100,1),new_transmute,4,FALSE), VLOOKUP(Midterm!AH6,new_transmute,4,FALSE) ), "" ) ) ) ) ) ) ) ) )) | AI6: =IF($B6="","", IF(AI$5="","", IF(Midterm!AI6="",0, IF(NOT(ISNUMBER(Midterm!AI6)),"NAN", IF(Midterm!AI6<0,"NEG", IF(Midterm!AI6>AI$5,"OVER", IF(AND(AI$5<=100,Midterm!AI6>100),"ERR", IF(Info!$B$4="Non-board program", IF(OR(AND(AI$5>0,AI$5>100),AND(AI$5>0,AI$5<100)), VLOOKUP(FLOOR((Midterm!AI6/AI$5)*100,1),new_transmute,2,FALSE), VLOOKUP(Midterm!AI6,new_transmute,2,FALSE) ), IF(Info!$B$4="Board program", IF(OR(AND(AI$5>0,AI$5>100),AND(AI$5>0,AI$5<100)), VLOOKUP(FLOOR((Midterm!AI6/AI$5)*100,1),new_transmute,3,FALSE), VLOOKUP(Midterm!AI6,new_transmute,3,FALSE) ), IF(Info!$B$4="Board program (Medicine)", IF(OR(AND(AI$5>0,AI$5>100),AND(AI$5>0,AI$5<100)), VLOOKUP(FLOOR((Midterm!AI6/AI$5)*100,1),new_transmute,4,FALSE), VLOOKUP(Midterm!AI6,new_transmute,4,FALSE) ), "" ) ) ) ) ) ) ) ) )) | AJ6: =IF($B6="","", IF(AJ$5="","", IF(Midterm!AJ6="",0, IF(NOT(ISNUMBER(Midterm!AJ6)),"NAN", IF(Midterm!AJ6<0,"NEG", IF(Midterm!AJ6>AJ$5,"OVER", IF(AND(AJ$5<=100,Midterm!AJ6>100),"ERR", IF(Info!$B$4="Non-board program", IF(OR(AND(AJ$5>0,AJ$5>100),AND(AJ$5>0,AJ$5<100)), VLOOKUP(FLOOR((Midterm!AJ6/AJ$5)*100,1),new_transmute,2,FALSE), VLOOKUP(Midterm!AJ6,new_transmute,2,FALSE) ), IF(Info!$B$4="Board program", IF(OR(AND(AJ$5>0,AJ$5>100),AND(AJ$5>0,AJ$5<100)), VLOOKUP(FLOOR((Midterm!AJ6/AJ$5)*100,1),new_transmute,3,FALSE), VLOOKUP(Midterm!AJ6,new_transmute,3,FALSE) ), IF(Info!$B$4="Board program (Medicine)", IF(OR(AND(AJ$5>0,AJ$5>100),AND(AJ$5>0,AJ$5<100)), VLOOKUP(FLOOR((Midterm!AJ6/AJ$5)*100,1),new_transmute,4,FALSE), VLOOKUP(Midterm!AJ6,new_transmute,4,FALSE) ), "" ) ) ) ) ) ) ) ) )) | AK6: =IF(B6="", "", IF(COUNTIF(AF6:AJ6, "OVER") > 0, "OVER", IFERROR(AVERAGEIF(AF6:AJ6, "<>OVER"), 0))) -> 0 | AL6: =IF(B6="", "", IF(OR(M6="OVER", S6="OVER", Y6="OVER", AE6="OVER", AK6="OVER"), "OVER", IF(Info!$B$4="Non-board program", VLOOKUP(IFERROR(FLOOR(SUM((M6*$M$4), (S6*$S$4), (Y6*$Y$4), (AE6*$AE$4), (AK6*$AK$4)) * (100 / 60), 1), 0), new_transmute, 2, FALSE), IF(Info!$B$4="Board program", VLOOKUP(IFERROR(FLOOR(SUM((M6*$M$4), (S6*$S$4), (Y6*$Y$4), (AE6*$AE$4), (AK6*$AK$4)) * (100 / 60), 1), 0), new_transmute, 3, FALSE), IF(Info!$B$4="Board program (Medicine)", VLOOKUP(IFERROR(FLOOR(SUM((M6*$M$4), (S6*$S$4), (Y6*$Y$4), (AE6*$AE$4), (AK6*$AK$4)) * (100 / 60), 1), 0), new_transmute, 4, FALSE), "" ) ) ) ) ) -> 96.9 | AM6: =IF($B6="","", IF(AM$5="","", IF(Midterm!AM6="",0, IF(NOT(ISNUMBER(Midterm!AM6)),"NAN", IF(Midterm!AM6<0,"NEG", IF(Midterm!AM6>AM$5,"OVER", IF(AND(AM$5<=100,Midterm!AM6>100),"ERR", IF(Info!$B$4="Non-board program", IF(OR(AND(AM$5>0,AM$5>100),AND(AM$5>0,AM$5<100)), VLOOKUP(FLOOR((Midterm!AM6/AM$5)*100,1),new_transmute,2,FALSE), VLOOKUP(Midterm!AM6,new_transmute,2,FALSE) ), IF(Info!$B$4="Board program", IF(OR(AND(AM$5>0,AM$5>100),AND(AM$5>0,AM$5<100)), VLOOKUP(FLOOR((Midterm!AM6/AM$5)*100,1),new_transmute,3,FALSE), VLOOKUP(Midterm!AM6,new_transmute,3,FALSE) ), IF(Info!$B$4="Board program (Medicine)", IF(OR(AND(AM$5>0,AM$5>100),AND(AM$5>0,AM$5<100)), VLOOKUP(FLOOR((Midterm!AM6/AM$5)*100,1),new_transmute,4,FALSE), VLOOKUP(Midterm!AM6,new_transmute,4,FALSE) ), "" ) ) ) ) ) ) ) ) )) | AN6: =IF($B6="","", IF(AN$5="","", IF(Midterm!AN6="",0, IF(NOT(ISNUMBER(Midterm!AN6)),"NAN", IF(Midterm!AN6<0,"NEG", IF(Midterm!AN6>AN$5,"OVER", IF(AND(AN$5<=100,Midterm!AN6>100),"ERR", IF(Info!$B$4="Non-board program", IF(OR(AND(AN$5>0,AN$5>100),AND(AN$5>0,AN$5<100)), VLOOKUP(FLOOR((Midterm!AN6/AN$5)*100,1),new_transmute,2,FALSE), VLOOKUP(Midterm!AN6,new_transmute,2,FALSE) ), IF(Info!$B$4="Board program", IF(OR(AND(AN$5>0,AN$5>100),AND(AN$5>0,AN$5<100)), VLOOKUP(FLOOR((Midterm!AN6/AN$5)*100,1),new_transmute,3,FALSE), VLOOKUP(Midterm!AN6,new_transmute,3,FALSE) ), IF(Info!$B$4="Board program (Medicine)", IF(OR(AND(AN$5>0,AN$5>100),AND(AN$5>0,AN$5<100)), VLOOKUP(FLOOR((Midterm!AN6/AN$5)*100,1),new_transmute,4,FALSE), VLOOKUP(Midterm!AN6,new_transmute,4,FALSE) ), "" ) ) ) ) ) ) ) ) )) | AO6: =IF($B6="","", IF(AO$5="","", IF(Midterm!AO6="",0, IF(NOT(ISNUMBER(Midterm!AO6)),"NAN", IF(Midterm!AO6<0,"NEG", IF(Midterm!AO6>AO$5,"OVER", IF(AND(AO$5<=100,Midterm!AO6>100),"ERR", IF(Info!$B$4="Non-board program", IF(OR(AND(AO$5>0,AO$5>100),AND(AO$5>0,AO$5<100)), VLOOKUP(FLOOR((Midterm!AO6/AO$5)*100,1),new_transmute,2,FALSE), VLOOKUP(Midterm!AO6,new_transmute,2,FALSE) ), IF(Info!$B$4="Board program", IF(OR(AND(AO$5>0,AO$5>100),AND(AO$5>0,AO$5<100)), VLOOKUP(FLOOR((Midterm!AO6/AO$5)*100,1),new_transmute,3,FALSE), VLOOKUP(Midterm!AO6,new_transmute,3,FALSE) ), IF(Info!$B$4="Board program (Medicine)", IF(OR(AND(AO$5>0,AO$5>100),AND(AO$5>0,AO$5<100)), VLOOKUP(FLOOR((Midterm!AO6/AO$5)*100,1),new_transmute,4,FALSE), VLOOKUP(Midterm!AO6,new_transmute,4,FALSE) ), "" ) ) ) ) ) ) ) ) )) | AP6: =IF($B6="","", IF(AP$5="","", IF(Midterm!AP6="",0, IF(NOT(ISNUMBER(Midterm!AP6)),"NAN", IF(Midterm!AP6<0,"NEG", IF(Midterm!AP6>AP$5,"OVER", IF(AND(AP$5<=100,Midterm!AP6>100),"ERR", IF(Info!$B$4="Non-board program", IF(OR(AND(AP$5>0,AP$5>100),AND(AP$5>0,AP$5<100)), VLOOKUP(FLOOR((Midterm!AP6/AP$5)*100,1),new_transmute,2,FALSE), VLOOKUP(Midterm!AP6,new_transmute,2,FALSE) ), IF(Info!$B$4="Board program", IF(OR(AND(AP$5>0,AP$5>100),AND(AP$5>0,AP$5<100)), VLOOKUP(FLOOR((Midterm!AP6/AP$5)*100,1),new_transmute,3,FALSE), VLOOKUP(Midterm!AP6,new_transmute,3,FALSE) ), IF(Info!$B$4="Board program (Medicine)", IF(OR(AND(AP$5>0,AP$5>100),AND(AP$5>0,AP$5<100)), VLOOKUP(FLOOR((Midterm!AP6/AP$5)*100,1),new_transmute,4,FALSE), VLOOKUP(Midterm!AP6,new_transmute,4,FALSE) ), "" ) ) ) ) ) ) ) ) )) -> 75 | AQ6: =IF(B6="", "", IF(COUNTIF(AM6:AP6, "OVER") > 0, "OVER", IFERROR(AVERAGEIF(AM6:AP6, "<>OVER"), 0))) -> 75 | AR6: =IF(Midterm!AR6="","",Midterm!AR6) -> 2 | AS6: =IF(B6="", "", IF(D6="Yes", "DRP", IF(D6="No", "WF", IFERROR(SUM(G6*$G$4, M6*$M$4, S6*$S$4, Y6*$Y$4, AE6*$AE$4, AK6*$AK$4, AQ6*$AQ$4, AR6), "ERR") ) ) ) -> 89.5 | AT6: =IF(B6="", "", IF(AS6="ERR", "ERR", IF(AS6="DRP", VLOOKUP(AS6, Equivalent, 1, FALSE), IF(AS6="WF", VLOOKUP(AS6, Equivalent, 1, FALSE), IF(E6="FA", VLOOKUP(E6, Equivalent, 1, FALSE), IF(AS6<60, 5, VLOOKUP(FLOOR(AS6, 1), Equivalent, 2, FALSE) ) ) ) ) ) ) -> 2 | AU6: =IF(B6="","",VLOOKUP(AT6,'New Grade Equivalent'!$B$3:$C$47,2,FALSE)) -> Pass
